# 错误处理方案

开发中我们会封装一些工具函数，封装之后给别人使用：在其他人使用的过程中，可能会传递一些参数；对于函数来说，需要对这些参数进行验证，否则可能得到的是我们不想要的结果；

很多时候我们可能验证到不是希望得到的参数时，就会直接return：但是return存在很大的弊端：调用者不知道是因为函数内部没有正常执行，还是执行结果就是一个undefined；事实上，正确的做法应该是如果没有通过某些验证，那么应该让外界知道函数内部报错了；

如何可以让一个函数告知外界自己内部出现了错误呢？**通过throw关键字，抛出一个异常**；

throw语句：throw语句用于抛出一个用户自定义的异常；当遇到throw语句时，当前的函数执行会被停止（throw后面的语句不会执行）；

如果我们执行代码，就会报错，拿到错误信息的时候我们可以及时的去修正代码。

```JS
  

    // 1.遇到一个错误, 造成后续的代码全部不能执行

    // function foo() {

    //   "abc".filter()

  

    //   console.log("第15行代码")

    //   console.log("-------")

    // }

  

    // foo()

    // console.log("+++++++++")

  

    // const btn = document.querySelector("button")

    // btn.onclick = function() {

    //   console.log("监听btn的点击")

    // }

  

    // 2.自己封装一些工具

    function sum(num1, num2) {

      if (typeof num1 !== "number") {

        throw "type error: num1传入的类型有问题, 必须是number类型"

      }

  

      if (typeof num2 !== "number") {

        throw "type error: num2传入的类型有问题, 必须是number类型"

      }

  

      return num1 + num2

    }

  

    // 李四调用

    const result = sum(123, 321)
```

## throw关键字

**throw表达式就是在throw后面可以跟上一个表达式来表示具体的异常信息**：
**throw expression**

throw关键字可以跟上哪些类型呢？ 
基本数据类型：比如number、string、Boolean
对象类型：对象类型可以包含更多的信息

```JS
 class HYError {

      constructor(message, code) {

        this.errMessage = message

        this.errCode = code

      }

    }

  

    // throw抛出一个异常

    // 1.函数中的代码遇到throw之后, 后续的代码都不会执行

    // 2.throw抛出一个具体的错误信息

    function foo() {

      console.log("foo function1")

      // 1.number/string/boolean

      // throw "反正就是一个错误"

  

      // 2.抛出一个对象

      // throw { errMessage: "我是错误信息", errCode: -1001 }

      // throw new HYError("错误信息", -1001)

  

      // 3.Error类: 错误函数的调用栈以及位置信息

      throw new Error("我是错误信息")

  

      console.log("foo function2")

      console.log("foo function3")

      console.log("foo function4")

    }

  

    function bar() {

      foo()

    }

  

    bar()
```

## Error类型

事实上，JavaScript已经给我们提供了一个Error类，我们可以直接创建这个类的对象：

```js
function foo() {
		throw new Error("error message","123")
}
```

Error包含三个属性：
- messsage：创建Error对象时传入的message；
- name：Error的名称，通常和类的名称一致；
- stack：整个Error的错误信息，包括函数的调用栈，当我们直接打印Error对象时，打印的就是stack；

Error有一些自己的子类：
- RangeError：下标值越界时使用的错误类型
- SyntaxError：解析语法错误时使用的错误类型；
- TypeError：出现类型错误时，使用的错误类型；

## 异常的处理

我们会发现在之前的代码中，一个函数抛出了异常，调用它的时候程序会被强制终止：这是因为如果我们在调用一个函数时，这个函数抛出了异常，但是我们并没有对这个异常进行处理，那么这个异常会继续传 递到上一个函数调用中；而如果到了最顶层（全局）的代码中依然没有对这个异常的处理代码，这个时候就会报错并且终止程序的运行；

## 异常的捕获

但是很多情况下当出现异常时，我们并不希望程序直接推出，而是希望可以正确的处理异常：这个时候我们就可以使用**try catch**

在ES10（ES2019）中，catch后面绑定的error可以省略。

当然，如果有一些必须要执行的代码，我们可以使用finally来执行：
finally表示最终一定会被执行的代码结构；

**注意：如果try和finally中都有返回值，那么会使用finally当中的返回值；**

```JS
 function foo() {

      console.log("foo function1")

      // throw new Error("我是错误信息")

      console.log("foo function2")

      console.log("foo function3")

      console.log("foo function4")

    }

  

    function test() {

      // 自己捕获了异常的话, 那么异常就不会传递给浏览器, 那么后续的代码可以正常执行

      try {

        foo()

        console.log("try后续的代码")

      } catch(error) {

        console.log("catch中的代码")

        // console.log(error)

      } finally {

        console.log("finally代码")

      }

    }

  

    function bar() {

      test()

    }

  

    bar()

  

    console.log("--------")
```

